(base) bkj@HOC-LX-BKJ:~/Dokumente/arise-prototype/django_prototype$ sudo docker-compose up
[sudo] Passwort f√ºr bkj: 
Starting django_prototype_db_1 ... done
Starting django_prototype_web_1 ... done
Attaching to django_prototype_db_1, django_prototype_web_1
db_1   | 
db_1   | PostgreSQL Database directory appears to contain a database; Skipping initialization
db_1   | 
db_1   | 2022-01-13 13:01:47.961 UTC [1] FATAL:  could not open directory "pg_notify": No such file or directory
db_1   | 2022-01-13 13:01:47.966 UTC [1] LOG:  database system is shut down
django_prototype_db_1 exited with code 1
web_1  | Watching for file changes with StatReloader
web_1  | Performing system checks...
web_1  | 
web_1  | System check identified no issues (0 silenced).
web_1  | Exception in thread django-main-thread:
web_1  | Traceback (most recent call last):
web_1  |   File "/usr/local/lib/python3.10/site-packages/django/db/backends/base/base.py", line 219, in ensure_connection
web_1  |     self.connect()
web_1  |   File "/usr/local/lib/python3.10/site-packages/django/utils/asyncio.py", line 33, in inner
web_1  |     return func(*args, **kwargs)
web_1  |   File "/usr/local/lib/python3.10/site-packages/django/db/backends/base/base.py", line 200, in connect
web_1  |     self.connection = self.get_new_connection(conn_params)
web_1  |   File "/usr/local/lib/python3.10/site-packages/django/utils/asyncio.py", line 33, in inner
web_1  |     return func(*args, **kwargs)
web_1  |   File "/usr/local/lib/python3.10/site-packages/django/db/backends/postgresql/base.py", line 187, in get_new_connection
web_1  |     connection = Database.connect(**conn_params)
web_1  |   File "/usr/local/lib/python3.10/site-packages/psycopg2/__init__.py", line 122, in connect
web_1  |     conn = _connect(dsn, connection_factory=connection_factory, **kwasync)
web_1  | psycopg2.OperationalError: could not translate host name "db" to address: Temporary failure in name resolution
web_1  | 
web_1  | 
web_1  | The above exception was the direct cause of the following exception:
web_1  | 
web_1  | Traceback (most recent call last):
web_1  |   File "/usr/local/lib/python3.10/threading.py", line 1009, in _bootstrap_inner
web_1  |     self.run()
web_1  |   File "/usr/local/lib/python3.10/threading.py", line 946, in run
web_1  |     self._target(*self._args, **self._kwargs)
web_1  |   File "/usr/local/lib/python3.10/site-packages/django/utils/autoreload.py", line 64, in wrapper
web_1  |     fn(*args, **kwargs)
web_1  |   File "/usr/local/lib/python3.10/site-packages/django/core/management/commands/runserver.py", line 121, in inner_run
web_1  |     self.check_migrations()
web_1  |   File "/usr/local/lib/python3.10/site-packages/django/core/management/base.py", line 486, in check_migrations
web_1  |     executor = MigrationExecutor(connections[DEFAULT_DB_ALIAS])
web_1  |   File "/usr/local/lib/python3.10/site-packages/django/db/migrations/executor.py", line 18, in __init__
web_1  |     self.loader = MigrationLoader(self.connection)
web_1  |   File "/usr/local/lib/python3.10/site-packages/django/db/migrations/loader.py", line 53, in __init__
web_1  |     self.build_graph()
web_1  |   File "/usr/local/lib/python3.10/site-packages/django/db/migrations/loader.py", line 220, in build_graph
web_1  |     self.applied_migrations = recorder.applied_migrations()
web_1  |   File "/usr/local/lib/python3.10/site-packages/django/db/migrations/recorder.py", line 77, in applied_migrations
web_1  |     if self.has_table():
web_1  |   File "/usr/local/lib/python3.10/site-packages/django/db/migrations/recorder.py", line 55, in has_table
web_1  |     with self.connection.cursor() as cursor:
web_1  |   File "/usr/local/lib/python3.10/site-packages/django/utils/asyncio.py", line 33, in inner
web_1  |     return func(*args, **kwargs)
web_1  |   File "/usr/local/lib/python3.10/site-packages/django/db/backends/base/base.py", line 259, in cursor
web_1  |     return self._cursor()
web_1  |   File "/usr/local/lib/python3.10/site-packages/django/db/backends/base/base.py", line 235, in _cursor
web_1  |     self.ensure_connection()
web_1  |   File "/usr/local/lib/python3.10/site-packages/django/utils/asyncio.py", line 33, in inner
web_1  |     return func(*args, **kwargs)
web_1  |   File "/usr/local/lib/python3.10/site-packages/django/db/backends/base/base.py", line 218, in ensure_connection
web_1  |     with self.wrap_database_errors:
web_1  |   File "/usr/local/lib/python3.10/site-packages/django/db/utils.py", line 90, in __exit__
web_1  |     raise dj_exc_value.with_traceback(traceback) from exc_value
web_1  |   File "/usr/local/lib/python3.10/site-packages/django/db/backends/base/base.py", line 219, in ensure_connection
web_1  |     self.connect()
web_1  |   File "/usr/local/lib/python3.10/site-packages/django/utils/asyncio.py", line 33, in inner
web_1  |     return func(*args, **kwargs)
web_1  |   File "/usr/local/lib/python3.10/site-packages/django/db/backends/base/base.py", line 200, in connect
web_1  |     self.connection = self.get_new_connection(conn_params)
web_1  |   File "/usr/local/lib/python3.10/site-packages/django/utils/asyncio.py", line 33, in inner
web_1  |     return func(*args, **kwargs)
web_1  |   File "/usr/local/lib/python3.10/site-packages/django/db/backends/postgresql/base.py", line 187, in get_new_connection
web_1  |     connection = Database.connect(**conn_params)
web_1  |   File "/usr/local/lib/python3.10/site-packages/psycopg2/__init__.py", line 122, in connect
web_1  |     conn = _connect(dsn, connection_factory=connection_factory, **kwasync)
web_1  | django.db.utils.OperationalError: could not translate host name "db" to address: Temporary failure in name resolution
web_1  | 
